Workbook

Sheet Dashboard
A1: Dashboard 14 Saham BEI
A2: Sel KUNING = input manual. Kolom PER, PBV, Yield, Payout, MoS, dan Perubahan dihitung otomatis dari input.
A3: Terakhir diperbarui: 2026-10-28 ← ubah tanggal ini setiap kali memperbarui harga
A4: IHSG | B4: 5236 | C4: -0.0082 | D4: penutupan 21 Okt 2026
A5: Kode | B5: Emiten | C5: Sektor | D5: Harga | E5: EPS TTM | F5: BVPS | G5: DPS TTM | H5: PER | I5: PER 5y | J5: PBV | K5: PBV 5y | L5: ROE | M5: Yield | N5: Payout | O5: Nilai Wajar | P5: MoS | Q5: Skor | R5: Rating | S5: Keputusan | T5: Harga 21 Okt | U5: Perubahan | V5: ROA (%) | W5: DER (x) | X5: EV/EBITDA (x) | Y5: Level Akumulasi | Z5: Level Beli | AA5: Target | AB5: Cut Loss | AC5: Ringkasan | AD5: Market Cap (Rp T) | AE5: PM (%) | AF5: OM (%) | AG5: CR (x) | AH5: ICR (x) | AI5: FCF | AJ5: Debt | AK5: Equity | AL5: Cash
A6: BMRI | B6: Bank Mandiri | C6: Bank | D6: 3790 | E6: 687.14 | F6: 3244.4016 | G6: 476.96 | H6: =IFERROR(D6/E6,"n/a") | I6: 10.24 | J6: =IFERROR(D6/F6,"n/a") | K6: 1.686 | L6: 0.2176 | M6: =IFERROR(G6/D6,"") | N6: =IFERROR(G6/E6,"") | O6: 6174.4124 | P6: =IFERROR((O6-D6)/O6,"") | Q6: 70.5 | R6: Menarik | S6: Buy | T6: 3700 | U6: =IFERROR(D6/T6-1,"") | Y6: 3.650 - 3.750 | Z6: 3.750 - 3.850 | AA6: 6174.4124 | AB6: 3600 | AC6: Bank · skor 70.5 · Menarik · Buy
A7: BBRI | B7: Bank Rakyat Indonesia | C7: Bank | D7: 2860 | E7: 406.65 | F7: 2181.245 | G7: 346 | H7: =IFERROR(D7/E7,"n/a") | I7: 13.76 | J7: =IFERROR(D7/F7,"n/a") | K7: 2.174 | L7: 0.1899 | M7: =IFERROR(G7/D7,"") | N7: =IFERROR(G7/E7,"") | O7: 3327.1508 | P7: =IFERROR((O7-D7)/O7,"") | Q7: 67 | R7: Menarik | S7: Buy (bertahap) | T7: 2810 | U7: =IFERROR(D7/T7-1,"") | Y7: 2.725 - 2.825 | Z7: 2.825 - 2.900 | AA7: 3327.1508 | AB7: 2675 | AC7: Bank · skor 67 · Menarik · Buy (bertahap)
A8: BBCA | B8: Bank Central Asia | C8: Bank | D8: 5075 | E8: 482.44 | F8: 2309.1827 | G8: 381 | H8: =IFERROR(D8/E8,"n/a") | I8: 23.476 | J8: =IFERROR(D8/F8,"n/a") | K8: 4.41 | L8: 0.212 | M8: =IFERROR(G8/D8,"") | N8: =IFERROR(G8/E8,"") | O8: 4162.0728 | P8: =IFERROR((O8-D8)/O8,"") | Q8: 58 | R8: Netral | S8: Wait and See | T8: 5275 | U8: =IFERROR(D8/T8-1,"") | Y8: 4.800 - 4.975 | Z8: 4.975 - 5.175 | AA8: 4162.0728 | AB8: 4725 | AC8: Bank · skor 58 · Netral · Wait and See
A9: BJBR | B9: Bank BJB | C9: Bank Daerah | D9: 720 | E9: 137.12 | F9: 1879.2776 | G9: 85.54 | H9: =IFERROR(D9/E9,"n/a") | I9: 6.452 | J9: =IFERROR(D9/F9,"n/a") | K9: 0.73 | L9: 0.0938 | M9: =IFERROR(G9/D9,"") | N9: =IFERROR(G9/E9,"") | O9: 1040.3743 | P9: =IFERROR((O9-D9)/O9,"") | Q9: 60.5 | R9: Menarik | S9: Buy (bertahap) | T9: 715 | U9: =IFERROR(D9/T9-1,"") | V9: 0.84 | Y9: 660 - 700 | Z9: 700 - 725 | AA9: 800 / 900 | AB9: 640 | AC9: Yield 12,0%, PB 0,38x, laba H1-2026 +58,8%, tetapi NPL naik ke 3,3% dan peringkat turun ke idAA-. Valuasi murah dengan risiko kualitas aset nyata: beli bertahap, posisi maksimal 12-14%. | AD9: 7.57 | AE9: 15.54 | AF9: 25.63 | AI9: 20970000 | AJ9: 43640000 | AK9: 19770000 | AL9: 21870000
A10: BJTM | B10: Bank Jatim | C10: Bank Daerah | D10: 496 | E10: 104.36 | F10: 1440.7457 | G10: 56.62 | H10: =IFERROR(D10/E10,"n/a") | I10: 6.452 | J10: =IFERROR(D10/F10,"n/a") | K10: 0.73 | L10: 0.1127 | M10: =IFERROR(G10/D10,"") | N10: =IFERROR(G10/E10,"") | O10: 966.26085 | P10: =IFERROR((O10-D10)/O10,"") | Q10: 59 | R10: Menarik | S10: Buy (bertahap) | T10: 498 | U10: =IFERROR(D10/T10-1,"") | V10: 1.46 | Y10: 465 - 490 | Z10: 490 - 505 | AA10: 540 / 605 | AB10: 460 | AC10: PB 0,35x, yield 11,4%, payout 55%: harga bank dalam kondisi stres. Kunci tesis adalah NPL 3,88%; jika kualitas aset stabil, re-rating ke PB 0,55 berarti +57%. Batasi posisi 8-10%. | AD10: 7.48 | AE10: 19.87 | AF10: 30.23 | AI10: -4803360 | AJ10: 15100000 | AK10: 21640000 | AL10: 15720000
A11: TLKM | B11: Telkom Indonesia | C11: Telekomunikasi | D11: 2060 | E11: 181.57 | F11: 1367.9245 | G11: 223.17 | H11: =IFERROR(D11/E11,"n/a") | I11: 16.254 | J11: =IFERROR(D11/F11,"n/a") | K11: 2.354 | L11: 0.1768 | M11: =IFERROR(G11/D11,"") | N11: =IFERROR(G11/E11,"") | O11: 2366.4988 | P11: =IFERROR((O11-D11)/O11,"") | Q11: 62 | R11: Menarik | S11: Buy (bertahap) | T11: 2080 | U11: =IFERROR(D11/T11-1,"") | V11: 7.58 | W11: 0.6 | X11: 3.49 | Y11: 1.850 - 2.000 | Z11: 2.000 - 2.100 | AA11: 2.450 / 2.900 | AB11: 1750 | AC11: De-rating ekstrem: PE 11,5x vs rata-rata 5 tahun 16,3x, PB 1,52x vs 2,35x, yield 10,7%. Laba stabil, katalis divestasi NeutraDC. Beli bertahap; payout di atas 100% dan tren turun menahan rekomendasi lebih kuat. | AD11: 210.97 | AE11: 12.01 | AF11: 24.19 | AG11: 0.79 | AH11: 7.8 | AI11: 43300000 | AJ11: 80890000 | AK11: 134850000 | AL11: 56480000
A12: HMSP | B12: HM Sampoerna | C12: Konsumsi | D12: 665 | E12: 73.73 | F12: 242.95048 | G12: 56.3 | H12: =IFERROR(D12/E12,"n/a") | I12: 13.582 | J12: =IFERROR(D12/F12,"n/a") | K12: 3.28 | L12: 0.3158 | M12: =IFERROR(G12/D12,"") | N12: =IFERROR(G12/E12,"") | O12: 782.78167 | P12: =IFERROR((O12-D12)/O12,"") | Q12: 53 | R12: Kurang Menarik | S12: Wait and See | T12: 645 | U12: =IFERROR(D12/T12-1,"") | Y12: 650 - 660 | Z12: 660 - 670 | AA12: 782.78167 | AB12: 640 | AC12: Konsumsi · skor 53 · Kurang Menarik · Wait and See
A13: CLEO | B13: Sariguna Primatirta | C13: Konsumsi | D13: 382 | E13: 17.92 | F13: 107.08333 | G13: 2.5 | H13: =IFERROR(D13/E13,"n/a") | I13: 32.214 | J13: =IFERROR(D13/F13,"n/a") | K13: 6.262 | L13: 0.1894 | M13: =IFERROR(G13/D13,"") | N13: =IFERROR(G13/E13,"") | O13: 478.17517 | P13: =IFERROR((O13-D13)/O13,"") | Q13: 50.5 | R13: Kurang Menarik | S13: Wait and See | T13: 400 | U13: =IFERROR(D13/T13-1,"") | Y13: 358 - 374 | Z13: 374 - 390 | AA13: 478.17517 | AB13: 350 | AC13: Konsumsi · skor 50.5 · Kurang Menarik · Wait and See
A14: ADRO | B14: Alamtri Resources | C14: Batubara & Energi | D14: 2430 | E14: 361.18 | F14: 3184.7222 | G14: 263.4 | H14: =IFERROR(D14/E14,"n/a") | I14: 4.348 | J14: =IFERROR(D14/F14,"n/a") | K14: 0.886 | L14: 0.1234 | M14: =IFERROR(G14/D14,"") | N14: =IFERROR(G14/E14,"") | O14: 2472.2552 | P14: =IFERROR((O14-D14)/O14,"") | Q14: 58.5 | R14: Netral | S14: Hold | T14: 2360 | U14: =IFERROR(D14/T14-1,"") | V14: 6.01 | W14: 0.38 | X14: 4.94 | Y14: 2.150 - 2.250 | Z14: 2.250 - 2.380 | AA14: 2.600 / 2.860 | AB14: 2150 | AC14: Yield 11,2% dan buyback menarik, tetapi PE 6,5x sudah di atas rata-rata historis, FCF negatif saat dividen sekitar 100% laba, dan harga batubara di puncak siklus. Hold; tunggu koreksi ke 2.150. Posisi satelit maksimal 8%. | AD14: 70.85 | AE14: 28.89 | AF14: 33.9 | AG14: 2.92 | AH14: 18.39 | AI14: -4604540 | AJ14: 34690000 | AK14: 91720000 | AL14: 28410000
A15: PTBA | B15: Bukit Asam | C15: Batubara | D15: 3100 | E15: 411.7 | F15: 2199.6528 | G15: 114.51 | H15: =IFERROR(D15/E15,"n/a") | I15: 5.436 | J15: =IFERROR(D15/F15,"n/a") | K15: 1.326 | L15: 0.2111 | M15: =IFERROR(G15/D15,"") | N15: =IFERROR(G15/E15,"") | O15: 2698.2198 | P15: =IFERROR((O15-D15)/O15,"") | Q15: 49 | R15: Kurang Menarik | S15: Wait and See | T15: 3080 | U15: =IFERROR(D15/T15-1,"") | V15: 6.78 | W15: 0.12 | X15: 4.14 | Y15: 2.800 - 2.950 | Z15: 2.950 - 3.080 | AA15: 3.400 / 3.600 | AB15: 2700 | AC15: Yield hanya 3,7%, harga naik 31% mendekati puncak 52 minggu, dan laba sangat bergantung pada harga batubara. Tidak memenuhi target passive income; tunggu koreksi. Untuk eksposur batubara, ADRO memiliki yield lebih baik. | AD15: 36.51 | AE15: 10.73 | AF15: 11.13 | AG15: 1.21 | AH15: 27.04 | AI15: 5540000 | AJ15: 2990000 | AK15: 25340000 | AL15: 7300000
A16: PGEO | B16: Pertamina Geothermal | C16: Energi Terbarukan | D16: 970 | E16: 63.17 | F16: 856.32458 | G16: 49.44 | H16: =IFERROR(D16/E16,"n/a") | I16: 18.226667 | J16: =IFERROR(D16/F16,"n/a") | K16: 1.39 | L16: 0.0751 | M16: =IFERROR(G16/D16,"") | N16: =IFERROR(G16/E16,"") | O16: 775.78917 | P16: =IFERROR((O16-D16)/O16,"") | Q16: 51.5 | R16: Kurang Menarik | S16: Wait and See | T16: 980 | U16: =IFERROR(D16/T16-1,"") | V16: 4.35 | W16: 0.37 | X16: 6.9 | Y16: 830 - 900 | Z16: 900 - 950 | AA16: 1.070 / 1.200 | AB16: 800 | AC16: Bisnis bagus dan prospek jangka panjang (target 1 GW 2028), tetapi yield 5% terlalu kecil dan valuasi belum mengompensasi risiko tarif serta ketergantungan PLN. Pantau; masuk hanya di 830-900. | AD16: 41.06 | AE16: 32.05 | AF16: 45.19 | AG16: 4.36 | AH16: 6.78 | AI16: 4070000 | AJ16: 13260000 | AK16: 35880000 | AL16: 11750000
A17: POWR | B17: Cikarang Listrindo | C17: Listrik / IPP | D17: 905 | E17: 78.53 | F17: 796.21451 | G17: 73.74 | H17: =IFERROR(D17/E17,"n/a") | I17: 8.896 | J17: =IFERROR(D17/F17,"n/a") | K17: 0.97 | L17: 0.0987 | M17: =IFERROR(G17/D17,"") | N17: =IFERROR(G17/E17,"") | O17: 701.24389 | P17: =IFERROR((O17-D17)/O17,"") | Q17: 59 | R17: Netral | S17: Wait and See | T17: 910 | U17: =IFERROR(D17/T17-1,"") | V17: 5.8 | W17: 0.49 | X17: 4.83 | Y17: 820 - 870 | Z17: 850 - 880 | AA17: 1.025 / 1.100 | AB17: 800 | AC17: Bisnis membaik dan cerita data center nyata, tetapi PE 30% di atas rata-rata historis dengan pertumbuhan laba masih negatif. Yield 8,1% belum mengompensasi risiko eksekusi. Pantau; akumulasi di 820-870. | AD17: 14.26 | AE17: 12.49 | AF17: 19.85 | AG17: 7.11 | AH17: 5.43 | AI17: 1390000 | AJ17: 6170000 | AK17: 12620000 | AL17: 5330000
A18: IPCC | B18: Indonesia Kendaraan Terminal | C18: Pelabuhan / Logistik | D18: 1015 | E18: 135.26 | F18: 719.78022 | G18: 112.85 | H18: =IFERROR(D18/E18,"n/a") | I18: 8.934 | J18: =IFERROR(D18/F18,"n/a") | K18: 1.136 | L18: 0.1912 | M18: =IFERROR(G18/D18,"") | N18: =IFERROR(G18/E18,"") | O18: 1075.2899 | P18: =IFERROR((O18-D18)/O18,"") | Q18: 63.5 | R18: Menarik | S18: Buy (posisi kecil) | T18: 990 | U18: =IFERROR(D18/T18-1,"") | V18: 9.75 | W18: 0.36 | X18: 3.35 | Y18: 900 - 950 | Z18: 950 - 1.000 | AA18: 1.100 / 1.250 | AB18: 880 | AC18: ROE 19,1%, neraca bersih, dividen besar dan bertumbuh (CAGR DPS 24,9%), yield 11,4%. Risiko: likuiditas tipis, tarif stagnan, tren teknikal turun. Beli posisi kecil maksimal 8%, akumulasi di 900-950. | AD18: 1.85 | AE18: 26.51 | AF18: 33.59 | AG18: 3.83 | AH18: 8.74 | AI18: 363750 | AJ18: 475730 | AK18: 1310000 | AL18: 1110000
A19: TUGU | B19: Asuransi Tugu Pratama | C19: Asuransi | D19: 1365 | E19: 258.69 | F19: 2811.7978 | G19: 99.99 | H19: =IFERROR(D19/E19,"n/a") | I19: 7.108 | J19: =IFERROR(D19/F19,"n/a") | K19: 0.358 | L19: 0.091 | M19: =IFERROR(G19/D19,"") | N19: =IFERROR(G19/E19,"") | O19: 1546.2576 | P19: =IFERROR((O19-D19)/O19,"") | Q19: 65.5 | R19: Menarik | S19: Buy | T19: 1345 | U19: =IFERROR(D19/T19-1,"") | V19: 1.95 | W19: 0.08 | X19: 5.07 | Y19: 1.235 - 1.300 | Z19: 1.300 - 1.380 | AA19: 1.570 / 1.705 | AB19: 1180 | AC19: Laba dan dividen tumbuh kuat (CAGR DPS 30,8%) dengan payout rendah 39%, valuasi PE 5,2x dan PB 0,48x di bawah rata-rata. Risiko: laba asuransi berayun dan ketergantungan pada Pertamina. Posisi 10-12%. | AD19: 4.91 | AE19: 15.99 | AF19: 16.85 | AG19: 35.07 | AH19: 13.77 | AI19: 466700 | AJ19: 837400 | AK19: 10010000 | AL19: 8230000
A21: Rata-rata / total portofolio | H21: =IFERROR(AVERAGE(H6:H19),"") | J21: =IFERROR(AVERAGE(J6:J19),"") | L21: =IFERROR(AVERAGE(L6:L19),"") | M21: =IFERROR(AVERAGE(M6:M19),"") | P21: =IFERROR(AVERAGE(P6:P19),"") | Q21: =IFERROR(AVERAGE(Q6:Q19),"")
A23: Catatan: Rating, Keputusan, Skor, PER 5y, PBV 5y, dan ROE adalah penilaian analis per 21 Okt 2026 — tidak berubah otomatis saat harga di-update. Lihat sheet 'Cara Update'.

Sheet Cara Update
A1: Cara Memperbarui Data
A2: Dashboard ini dirancang agar pembaruan bulanan hanya butuh mengubah beberapa sel. Yang otomatis dihitung ulang: PER, PBV, Yield, Payout, MoS, dan Perubahan harga.
A4: Bagian | B4: Otomatis? | C4: Cara memperbarui / catatan
A5: Harga saham | B5: Ya (formula) | C5: Ubah kolom D di sheet Dashboard. PER, PBV, Yield, Payout, MoS, dan % Perubahan langsung menyesuaikan.
A6: EPS TTM | B6: Manual | C6: Kolom E. Perbarui setelah rilis laporan keuangan (Q1/Q2/Q3/FY) dari laporan emiten atau keterbukaan BEI.
A7: BVPS (ekuitas/saham) | B7: Manual | C7: Kolom F. Hitung dari ekuitas ÷ jumlah saham pada laporan terbaru.
A8: DPS 12 bulan terakhir | B8: Manual | C8: Kolom G. Perbarui setelah RUPS menetapkan dividen (umumnya Mei–Juli).
A9: Nilai wajar | B9: Manual | C9: Kolom O. Hanya berubah bila asumsi berubah (PE wajar, pertumbuhan, biaya ekuitas) — bukan karena harga bergerak.
A10: Skor, Rating, Keputusan | B10: Tidak | C10: Penilaian analis, bukan rumus. Perlu ditinjau ulang bila harga bergerak >15% atau fundamental berubah.
A11: Simulator & Proyeksi | B11: Ya | C11: Ubah sel kuning di sheet Simulator. Nilai portofolio, dividen, dan tahun target otomatis dihitung ulang.
A12: Data Keuangan & Teknikal | B12: Tidak | C12: Snapshot 21 Okt 2026. Perbarui manual dari laporan keuangan dan data harga terbaru.
A15: LANGKAH UPDATE BULANAN
A16: 1. Ambil harga penutupan terakhir dari broker, IDX, RTI, Stockbit, atau TradingView.
A17: 2. Isi kolom D (Harga). Kolom T (Harga 21 Okt) dibiarkan sebagai basis pembanding perubahan.
A18: 3. Ubah teks tanggal di baris 3 (sel A3).
A19: 4. Setelah rilis laporan keuangan: perbarui EPS, BVPS, dan DPS. Setelah RUPS: perbarui DPS.
A20: 5. Tinjau ulang skor/rating secara manual — terutama jika MoS berubah melewati ±20%.
A23: OPSI OTOMATIS DARI INTERNET
A24: Excel (Power Query) | B24: Bisa menarik tabel dari web (Data > Dapatkan Data > Dari Web), tetapi IDX dan Yahoo Finance tidak menyediakan endpoint publik gratis yang stabil. Hasilnya sering gagal atau berubah format — tidak saya rekomendasikan untuk mengandalkan update otomatis penuh.
A25: Google Sheets | B25: Mendukung harga otomatis lewat GOOGLEFINANCE. Impor file ini ke Google Drive, lalu di sheet Dashboard ganti kolom D dengan formula (pemisah argumen bisa koma atau titik koma tergantung locale):
B26: =GOOGLEFINANCE("IDX:BJBR","price")
B27: =GOOGLEFINANCE("IDX:BJBR","closeyest")
A29: Batasan: GOOGLEFINANCE hanya menyediakan harga (dan sebagian data pasar). EPS, BVPS, DPS, dan nilai wajar tetap harus diperbarui manual — jadi otomatisasi penuh tidak mungkin tanpa langganan data.
A31: TOMBOL REFRESH HARGA (MAKRO VBA)
A32: 1. Simpan workbook ini sebagai file .xlsm: File > Save As > pilih 'Excel Macro-Enabled Workbook (*.xlsm)'.
A33: 2. Tekan Alt+F11 (membuka editor VBA), lalu File > Import File > pilih 'RefreshHarga.bas'.
A34: 3. Tekan Alt+F8, pilih 'PasangTombol', klik Run. Tombol 'Refresh Harga' muncul di sheet Dashboard (pojok kanan atas).
A35: 4. Klik tombol itu kapan pun. Harga terisi, tanggal diperbarui, dan seluruh rasio menghitung ulang otomatis.
A36: 5. Jika Excel memblokir makro: File > Options > Trust Center > Macro Settings > pilih 'Enable VBA macros'.
A38: Catatan: tombol tidak bisa ditanam ke file .xlsx biasa — Excel hanya menjalankan makro dari .xlsm. Sumber harga: Yahoo Finance, dapat delayed 15–20 menit. Bila pengambilan gagal, harga lama tidak diubah.
A40: VERSI_TEMPLATE | B40: 2.0 | C40: Template dengan Data Keuangan tidy + Ringkasan 5 Tahun.
A41: Data Keuangan | B41: Tabel tidy | C41: Satu baris per emiten-tahun; lihat sheet Data Keuangan.
A42: ROA / DER / EV | B42: Otomatis | C42: Dihitung dari total aset/ekuitas/utang/EBITDA jika tersedia.
A43: Skor faktor | B43: Manual | C43: Sheet Skor; 0–10 per faktor. Total 0–100 dari Dashboard.
A44: Historik harga | B44: Manual | C44: Sheet Historik; minimal 10 minggu per saham.

Sheet Valuasi & Skenario
A1: Valuasi, Nilai Wajar, dan Skenario Harga
A2: Harga, EPS, dan MoS terhubung ke sheet Dashboard. Angka skenario adalah snapshot model 21 Okt 2026 — tidak berubah otomatis bila harga di-update.
A4: Kode | B4: Harga | C4: EPS TTM | D4: PE wajar | E4: Nilai Wajar | F4: MoS | G4: Metode | H4: Bull 1y | I4: Bull 3y | J4: Bull 5y | K4: Base 1y | L4: Base 3y | M4: Base 5y | N4: Bear 1y | O4: Bear 3y | P4: Bear 5y | Q4: Upside base 1y | S4: DDM | T4: PB Wajar | U4: FV Low | V4: FV High | W4: DDM Low | X4: DDM High
A5: BMRI | B5: ='Dashboard'!D6 | C5: ='Dashboard'!E6 | D5: 9 | E5: 6174.4124 | F5: ='Dashboard'!P6 | G5: 60% PB + 40% DDM | H5: 5838.4255 | I5: 8958.9445 | J5: 10449.713 | K5: 5189.2365 | L5: 7159.054 | M5: 7892.857 | N5: 3894.0563 | O5: 3950.945 | P5: 3717.4441 | Q5: =K5/B5-1 | S5: 4678.7505 | T5: 1.6118519 | U5: 3717.4441 | V5: 10449.713 | W5: 3976.9379 | X5: 5380.563
A6: BBRI | B6: ='Dashboard'!D7 | C6: ='Dashboard'!E7 | D6: 8.5 | E6: 3327.1508 | F6: ='Dashboard'!P7 | G6: 60% PB + 40% DDM | H6: 3663.902 | I6: 5007.3599 | J6: 5840.5846 | K6: 3289.9256 | L6: 4001.3598 | M6: 4411.4991 | N6: 2536.3402 | O6: 2208.2739 | P6: 2077.7649 | Q6: =K6/B6-1 | S6: 3394.0952 | T6: 1.4066667 | U6: 2077.7649 | V6: 5840.5846 | W6: 2884.981 | X6: 3903.2095
A7: BBCA | B7: ='Dashboard'!D8 | C7: ='Dashboard'!E8 | D7: 9 | E7: 4162.0728 | F7: ='Dashboard'!P8 | G7: 60% PB + 40% DDM | H7: 5596.1984 | I7: 6466.4087 | J7: 7682.7402 | K7: 5096.9888 | L7: 5171.3438 | M7: 5810.5219 | N7: 4074.0423 | O7: 2860.6326 | P7: 2747.3516 | Q7: =K7/B7-1 | S7: 3737.4286 | T7: 1.5703704 | U7: 2747.3516 | V7: 7682.7402 | W7: 3176.8143 | X7: 4298.0429
A8: BJBR | B8: ='Dashboard'!D9 | C8: ='Dashboard'!E9 | D8: 6 | E8: 1040.3743 | F8: ='Dashboard'!P9 | G8: 60% PB + 40% DDM | H8: 897.00912 | I8: 1191.8488 | J8: 1390.1724 | K8: 799.6144 | L8: 925.44811 | M8: 1000.9647 | N8: 619.63392 | O8: 509.523 | P8: 469.5764 | Q8: =K8/B8-1 | S8: 888.11 | T8: 0.608 | U8: 771.98 | V8: 1165.22 | W8: 771.98 | X8: 1045.36
A9: BJTM | B9: ='Dashboard'!D10 | C9: ='Dashboard'!E10 | D9: 6 | E9: 966.26085 | F9: ='Dashboard'!P10 | G9: 60% PB + 40% DDM | H9: 663.85578 | I9: 932.52966 | J9: 1107.9385 | K9: 590.184 | L9: 724.85847 | M9: 799.15646 | N9: 454.11132 | O9: 400.03553 | P9: 376.39343 | Q9: =K9/B9-1 | S9: 713.51 | T9: 0.788 | U9: 604.8 | V9: 1082.21 | W9: 604.8 | X9: 869.88
A10: TLKM | B10: ='Dashboard'!D11 | C10: ='Dashboard'!E11 | D10: 14 | E10: 2366.4988 | F10: ='Dashboard'!P11 | G10: 45% PE + 35% DDM + 20% PB | H10: 2651.7368 | I10: 3481.6697 | J10: 3912.0041 | K10: 2357.2098 | L10: 2697.5695 | M10: 2806.5513 | N10: 1813.9114 | O10: 1477.9295 | P10: 1305.8985 | Q10: =K10/B10-1 | S10: 1653.11 | U10: 1487.8 | V10: 2650.48 | W10: 1487.8 | X10: 1859.75
A11: HMSP | B11: ='Dashboard'!D12 | C11: ='Dashboard'!E12 | D11: 10.5 | E11: 782.78167 | F11: ='Dashboard'!P12 | G11: 60% PE + 40% DDM | H11: 790.67422 | I11: 972.84365 | J11: 1032.0898 | K11: 709.5825 | L11: 774.165 | M11: 774.165 | N11: 557.85028 | O11: 450.10634 | P11: 397.71397 | Q11: =K11/B11-1 | S11: 552.27619 | T11: 2.3392593 | U11: 397.71397 | V11: 1032.0898 | W11: 469.43476 | X11: 635.11762
A12: CLEO | B12: ='Dashboard'!D13 | C12: ='Dashboard'!E13 | D12: 24 | E12: 478.17517 | F12: ='Dashboard'!P13 | G12: 80% PE + 20% PB | H12: 492.0256 | I12: 658.30195 | J12: 796.54536 | K12: 439.9424 | L12: 512.23216 | M12: 575.54406 | N12: 343.51744 | O12: 283.3515 | P12: 272.13078 | Q12: =K12/B12-1 | S12: 24.52381 | T12: 1.402963 | U12: 272.13078 | V12: 796.54536 | W12: 20.845238 | X12: 28.202381
A13: ADRO | B13: ='Dashboard'!D14 | C13: ='Dashboard'!E14 | D13: 6.2 | E13: 2472.2552 | F13: ='Dashboard'!P14 | G13: 60% PE + 40% PB | H13: 2615.6631 | I13: 3067.1204 | J13: 3446.2164 | K13: 2253.6648 | L13: 2107.6263 | M13: 2024.1643 | N13: 1728.1093 | O13: 1068.2218 | P13: 827.23097 | Q13: =K13/B13-1 | S13: 2679.32 | U13: 2175.58 | V13: 3143.45 | W13: 2334.62 | X13: 3143.45
A14: PTBA | B14: ='Dashboard'!D15 | C14: ='Dashboard'!E15 | D14: 6.2 | E14: 2698.2198 | F14: ='Dashboard'!P15 | G14: 60% PE + 40% PB | H14: 3158.096 | I14: 3398.1167 | J14: 3746.4237 | K14: 2731.7819 | L14: 2329.6343 | M14: 2191.9529 | N14: 2141.3823 | O14: 1217.6392 | P14: 942.93978 | Q14: =K14/B14-1 | S14: 1618.41 | U14: 1348.67 | V14: 3022.01 | W14: 1348.67 | X14: 2023.01
A15: PGEO | B15: ='Dashboard'!D16 | C15: ='Dashboard'!E16 | D15: 16 | E15: 775.78917 | F15: ='Dashboard'!P16 | G15: 60% PE + 40% DDM | H15: 1178.2804 | I15: 1547.0586 | J15: 1871.9409 | K15: 1055.0816 | L15: 1203.7837 | M15: 1352.5714 | N15: 843.752 | O15: 707.504 | P15: 707.504 | Q15: =K15/B15-1 | S15: 423.39 | U15: 375.88 | V15: 868.88 | W15: 375.88 | X15: 484.65
A16: POWR | B16: ='Dashboard'!D17 | C16: ='Dashboard'!E17 | D16: 10 | E16: 701.24389 | F16: ='Dashboard'!P17 | G16: 60% PE + 40% DDM | H16: 970.00583 | I16: 1106.3302 | J16: 1266.6375 | K16: 873.0795 | L16: 858.11851 | M16: 910.37793 | N16: 700.6608 | O16: 486.34823 | P16: 448.21853 | Q16: =K16/B16-1 | S16: 575.16 | U16: 515.24 | V16: 785.39 | W16: 515.24 | X16: 650.85
A17: IPCC | B17: ='Dashboard'!D18 | C17: ='Dashboard'!E18 | D17: 8.5 | E17: 1075.2899 | F17: ='Dashboard'!P18 | G17: 45% PE + 35% DDM + 20% PB | H17: 1248.5699 | I17: 1665.549 | J17: 1942.6964 | K17: 1112.6492 | L17: 1293.2674 | M17: 1398.798 | N17: 852.52857 | O17: 690.01283 | P17: 622.73658 | Q17: =K17/B17-1 | S17: 1126.82 | U17: 946.26 | V17: 1318.19 | W17: 983.97 | X17: 1318.19
A18: TUGU | B18: ='Dashboard'!D19 | C18: ='Dashboard'!E19 | D18: 6.8 | E18: 1546.2576 | F18: ='Dashboard'!P19 | G18: 50% PE + 50% DDM | H18: 1852.3757 | I18: 2692.5542 | J18: 3257.9905 | K18: 1629.6483 | L18: 2036.3689 | M18: 2245.0967 | N18: 1210.8913 | O18: 1022.7516 | P18: 903.70329 | Q18: =K18/B18-1 | S18: 1333.42 | U18: 1121.04 | V18: 1731.81 | W18: 1121.04 | X18: 1645.1

Sheet Simulator
A1: Simulator Financial Freedom
A2: Ubah sel kuning. Semua hasil dihitung ulang otomatis (model bulanan, dividen direinvestasikan).
A4: ASUMSI | D4: HASIL PADA HORIZON
A5: Setoran bulanan (Rp) | B5: 5000000
A6: Dividend yield awal | B6: 0.08 | D6: Total setoran | E6: =B5*12*B9
A7: Pertumbuhan dividen / tahun | B7: 0.05 | D7: Nilai portofolio | E7: =INDEX(Simulasi!$E$5:$E$364,B9*12)
A8: Pertumbuhan harga / tahun | B8: 0.05 | D8: Dividen tahunan | E8: =INDEX(Simulasi!$F$5:$F$364,B9*12)
A9: Horizon (tahun, maks 30) | B9: 20 | D9: Dividen bulanan | E9: =E8/12
D10: Kelipatan modal | E10: =E7/E6
A12: TARGET PASSIVE INCOME
A13: Target dividen / bulan (Rp) | B13: 10000000 | D13: Modal yang dibutuhkan | E13: =B13*12/B6
D14: Tahun tercapai (simulasi) | E14: =IF(COUNTIF(Simulasi!$F$5:$F$364,"<"&(B13*12))>=360,"belum tercapai",(COUNTIF(Simulasi!$F$5:$F$364,"<"&(B13*12))+1)/12)

Sheet Proyeksi Tahunan
A1: Proyeksi Nilai Portofolio per Tahun
A2: Bersumber dari sheet 'Simulasi'. Mengikuti asumsi di sheet 'Simulator'.
A4: Tahun | B4: Nilai Portofolio | C4: Total Setoran Kumulatif | D4: Dividen / Tahun | E4: Dividen / Bulan | F4: Yield on Cost
A5: 1 | B5: =IF($A5>Simulator!$B$9,"",INDEX(Simulasi!$E$5:$E$364,$A5*12)) | C5: =IF($A5>Simulator!$B$9,"",Simulator!$B$5*12*$A5) | D5: =IF($A5>Simulator!$B$9,"",INDEX(Simulasi!$F$5:$F$364,$A5*12)) | E5: =IF($A5>Simulator!$B$9,"",D5/12) | F5: =IF($A5>Simulator!$B$9,"",D5/C5)
A6: 2 | B6: =IF($A6>Simulator!$B$9,"",INDEX(Simulasi!$E$5:$E$364,$A6*12)) | C6: =IF($A6>Simulator!$B$9,"",Simulator!$B$5*12*$A6) | D6: =IF($A6>Simulator!$B$9,"",INDEX(Simulasi!$F$5:$F$364,$A6*12)) | E6: =IF($A6>Simulator!$B$9,"",D6/12) | F6: =IF($A6>Simulator!$B$9,"",D6/C6)
A7: 3 | B7: =IF($A7>Simulator!$B$9,"",INDEX(Simulasi!$E$5:$E$364,$A7*12)) | C7: =IF($A7>Simulator!$B$9,"",Simulator!$B$5*12*$A7) | D7: =IF($A7>Simulator!$B$9,"",INDEX(Simulasi!$F$5:$F$364,$A7*12)) | E7: =IF($A7>Simulator!$B$9,"",D7/12) | F7: =IF($A7>Simulator!$B$9,"",D7/C7)
A8: 4 | B8: =IF($A8>Simulator!$B$9,"",INDEX(Simulasi!$E$5:$E$364,$A8*12)) | C8: =IF($A8>Simulator!$B$9,"",Simulator!$B$5*12*$A8) | D8: =IF($A8>Simulator!$B$9,"",INDEX(Simulasi!$F$5:$F$364,$A8*12)) | E8: =IF($A8>Simulator!$B$9,"",D8/12) | F8: =IF($A8>Simulator!$B$9,"",D8/C8)
A9: 5 | B9: =IF($A9>Simulator!$B$9,"",INDEX(Simulasi!$E$5:$E$364,$A9*12)) | C9: =IF($A9>Simulator!$B$9,"",Simulator!$B$5*12*$A9) | D9: =IF($A9>Simulator!$B$9,"",INDEX(Simulasi!$F$5:$F$364,$A9*12)) | E9: =IF($A9>Simulator!$B$9,"",D9/12) | F9: =IF($A9>Simulator!$B$9,"",D9/C9)
A10: 6 | B10: =IF($A10>Simulator!$B$9,"",INDEX(Simulasi!$E$5:$E$364,$A10*12)) | C10: =IF($A10>Simulator!$B$9,"",Simulator!$B$5*12*$A10) | D10: =IF($A10>Simulator!$B$9,"",INDEX(Simulasi!$F$5:$F$364,$A10*12)) | E10: =IF($A10>Simulator!$B$9,"",D10/12) | F10: =IF($A10>Simulator!$B$9,"",D10/C10)
A11: 7 | B11: =IF($A11>Simulator!$B$9,"",INDEX(Simulasi!$E$5:$E$364,$A11*12)) | C11: =IF($A11>Simulator!$B$9,"",Simulator!$B$5*12*$A11) | D11: =IF($A11>Simulator!$B$9,"",INDEX(Simulasi!$F$5:$F$364,$A11*12)) | E11: =IF($A11>Simulator!$B$9,"",D11/12) | F11: =IF($A11>Simulator!$B$9,"",D11/C11)
A12: 8 | B12: =IF($A12>Simulator!$B$9,"",INDEX(Simulasi!$E$5:$E$364,$A12*12)) | C12: =IF($A12>Simulator!$B$9,"",Simulator!$B$5*12*$A12) | D12: =IF($A12>Simulator!$B$9,"",INDEX(Simulasi!$F$5:$F$364,$A12*12)) | E12: =IF($A12>Simulator!$B$9,"",D12/12) | F12: =IF($A12>Simulator!$B$9,"",D12/C12)
A13: 9 | B13: =IF($A13>Simulator!$B$9,"",INDEX(Simulasi!$E$5:$E$364,$A13*12)) | C13: =IF($A13>Simulator!$B$9,"",Simulator!$B$5*12*$A13) | D13: =IF($A13>Simulator!$B$9,"",INDEX(Simulasi!$F$5:$F$364,$A13*12)) | E13: =IF($A13>Simulator!$B$9,"",D13/12) | F13: =IF($A13>Simulator!$B$9,"",D13/C13)
A14: 10 | B14: =IF($A14>Simulator!$B$9,"",INDEX(Simulasi!$E$5:$E$364,$A14*12)) | C14: =IF($A14>Simulator!$B$9,"",Simulator!$B$5*12*$A14) | D14: =IF($A14>Simulator!$B$9,"",INDEX(Simulasi!$F$5:$F$364,$A14*12)) | E14: =IF($A14>Simulator!$B$9,"",D14/12) | F14: =IF($A14>Simulator!$B$9,"",D14/C14)
A15: 11 | B15: =IF($A15>Simulator!$B$9,"",INDEX(Simulasi!$E$5:$E$364,$A15*12)) | C15: =IF($A15>Simulator!$B$9,"",Simulator!$B$5*12*$A15) | D15: =IF($A15>Simulator!$B$9,"",INDEX(Simulasi!$F$5:$F$364,$A15*12)) | E15: =IF($A15>Simulator!$B$9,"",D15/12) | F15: =IF($A15>Simulator!$B$9,"",D15/C15)
A16: 12 | B16: =IF($A16>Simulator!$B$9,"",INDEX(Simulasi!$E$5:$E$364,$A16*12)) | C16: =IF($A16>Simulator!$B$9,"",Simulator!$B$5*12*$A16) | D16: =IF($A16>Simulator!$B$9,"",INDEX(Simulasi!$F$5:$F$364,$A16*12)) | E16: =IF($A16>Simulator!$B$9,"",D16/12) | F16: =IF($A16>Simulator!$B$9,"",D16/C16)
... A34: 30 | B34: =IF($A34>Simulator!$B$9,"",INDEX(Simulasi!$E$5:$E$364,$A34*12)) | C34: =IF($A34>Simulator!$B$9,"",Simulator!$B$5*12*$A34) | D34: =IF($A34>Simulator!$B$9,"",INDEX(Simulasi!$F$5:$F$364,$A34*12)) | E34: =IF($A34>Simulator!$B$9,"",D34/12) | F34: =IF($A34>Simulator!$B$9,"",D34/C34)

Sheet Simulasi
A1: Mesin simulasi bulanan — jangan ubah rumus
A3: Bulan | B3: Harga (indeks) | C3: DPS (indeks) | D3: Lembar | E3: Nilai | F3: Dividen Run-Rate
B4: 1 | C4: =Simulator!$B$6 | D4: 0
A5: 1 | B5: =B4*(1+Simulator!$B$8)^(1/12) | C5: =IF(AND(A5>1,MOD(A5-1,12)=0),C4*(1+Simulator!$B$7),C4) | D5: =D4+(Simulator!$B$5+D4*C5/12)/B5 | E5: =D5*B5 | F5: =D5*C5
A6: 2 | B6: =B5*(1+Simulator!$B$8)^(1/12) | C6: =IF(AND(A6>1,MOD(A6-1,12)=0),C5*(1+Simulator!$B$7),C5) | D6: =D5+(Simulator!$B$5+D5*C6/12)/B6 | E6: =D6*B6 | F6: =D6*C6
A7: 3 | B7: =B6*(1+Simulator!$B$8)^(1/12) | C7: =IF(AND(A7>1,MOD(A7-1,12)=0),C6*(1+Simulator!$B$7),C6) | D7: =D6+(Simulator!$B$5+D6*C7/12)/B7 | E7: =D7*B7 | F7: =D7*C7
A8: 4 | B8: =B7*(1+Simulator!$B$8)^(1/12) | C8: =IF(AND(A8>1,MOD(A8-1,12)=0),C7*(1+Simulator!$B$7),C7) | D8: =D7+(Simulator!$B$5+D7*C8/12)/B8 | E8: =D8*B8 | F8: =D8*C8
A9: 5 | B9: =B8*(1+Simulator!$B$8)^(1/12) | C9: =IF(AND(A9>1,MOD(A9-1,12)=0),C8*(1+Simulator!$B$7),C8) | D9: =D8+(Simulator!$B$5+D8*C9/12)/B9 | E9: =D9*B9 | F9: =D9*C9
A10: 6 | B10: =B9*(1+Simulator!$B$8)^(1/12) | C10: =IF(AND(A10>1,MOD(A10-1,12)=0),C9*(1+Simulator!$B$7),C9) | D10: =D9+(Simulator!$B$5+D9*C10/12)/B10 | E10: =D10*B10 | F10: =D10*C10
A11: 7 | B11: =B10*(1+Simulator!$B$8)^(1/12) | C11: =IF(AND(A11>1,MOD(A11-1,12)=0),C10*(1+Simulator!$B$7),C10) | D11: =D10+(Simulator!$B$5+D10*C11/12)/B11 | E11: =D11*B11 | F11: =D11*C11
A12: 8 | B12: =B11*(1+Simulator!$B$8)^(1/12) | C12: =IF(AND(A12>1,MOD(A12-1,12)=0),C11*(1+Simulator!$B$7),C11) | D12: =D11+(Simulator!$B$5+D11*C12/12)/B12 | E12: =D12*B12 | F12: =D12*C12
A13: 9 | B13: =B12*(1+Simulator!$B$8)^(1/12) | C13: =IF(AND(A13>1,MOD(A13-1,12)=0),C12*(1+Simulator!$B$7),C12) | D13: =D12+(Simulator!$B$5+D12*C13/12)/B13 | E13: =D13*B13 | F13: =D13*C13
A14: 10 | B14: =B13*(1+Simulator!$B$8)^(1/12) | C14: =IF(AND(A14>1,MOD(A14-1,12)=0),C13*(1+Simulator!$B$7),C13) | D14: =D13+(Simulator!$B$5+D13*C14/12)/B14 | E14: =D14*B14 | F14: =D14*C14
A15: 11 | B15: =B14*(1+Simulator!$B$8)^(1/12) | C15: =IF(AND(A15>1,MOD(A15-1,12)=0),C14*(1+Simulator!$B$7),C14) | D15: =D14+(Simulator!$B$5+D14*C15/12)/B15 | E15: =D15*B15 | F15: =D15*C15
A16: 12 | B16: =B15*(1+Simulator!$B$8)^(1/12) | C16: =IF(AND(A16>1,MOD(A16-1,12)=0),C15*(1+Simulator!$B$7),C15) | D16: =D15+(Simulator!$B$5+D15*C16/12)/B16 | E16: =D16*B16 | F16: =D16*C16
... A364: 360 | B364: =B363*(1+Simulator!$B$8)^(1/12) | C364: =IF(AND(A364>1,MOD(A364-1,12)=0),C363*(1+Simulator!$B$7),C363) | D364: =D363+(Simulator!$B$5+D363*C364/12)/B364 | E364: =D364*B364 | F364: =D364*C364

Sheet Data Keuangan (lama)
A1: Data Keuangan 2021–2025
A2: ADRO, PGEO, POWR dilaporkan dalam US$ juta. Lainnya dalam Rp triliun.
A4: BMRI — Bank Mandiri
A5: Indikator | B5: 2021 | C5: 2022 | D5: 2023 | E5: 2024 | F5: 2025 | G5: TTM
A6: Pendapatan (Rp T) | B6: 86.552332 | C6: 109.39753 | D6: 127.45457 | E6: 134.73536 | F6: 144.81748 | G6: 139.87246
A7: Laba bersih (Rp T) | B7: 28.028155 | C7: 41.170637 | D7: 55.060057 | E7: 55.782742 | F7: 56.29395 | G7: 64.097809
A8: EPS (Rp) | B8: 300.53 | C8: 441.26 | D8: 589.93 | E8: 597.67 | F8: 603.23 | G8: 687.14
A9: DPS (Rp) | B9: n/a | C9: 180.32 | D9: 264.67 | E9: 353.96 | F9: 466.18 | G9: 476.96
A11: BBRI — Bank Rakyat Indonesia
A12: Indikator | B12: 2021 | C12: 2022 | D12: 2023 | E12: 2024 | F12: 2025 | G12: TTM
A13: Pendapatan (Rp T) | B13: 111.5854 | C13: 125.99009 | D13: 137.05849 | E13: 131.25363 | F13: 140.20883 | G13: 146.8427
A14: Laba bersih (Rp T) | B14: 31.066592 | C14: 51.170312 | D14: 60.099863 | E14: 59.944649 | F14: 56.652384 | G14: 61.241085
A15: EPS (Rp) | B15: 237.96 | C15: 338 | D15: 398 | E15: 397.69 | F15: 376 | G15: 406.65
A16: DPS (Rp) | B16: n/a | C16: 174.25 | D16: 288.22 | E16: 319 | F16: 345.4 | G16: 346
A18: BBCA — Bank Central Asia
A19: Indikator | B19: 2021 | C19: 2022 | D19: 2023 | E19: 2024 | F19: 2025 | G19: TTM
A20: Pendapatan (Rp T) | B20: 69.144054 | C20: 82.942762 | D20: 97.444628 | E20: 104.5166 | F20: 107.98561 | G20: 110.55051
A21: Laba bersih (Rp T) | B21: 31.42266 | C21: 40.735722 | D21: 48.639122 | E21: 54.836305 | F21: 57.537287 | G21: 59.355699
A22: EPS (Rp) | B22: 254.9 | C22: 330 | D22: 394.56 | E22: 444.83 | F22: 466.85 | G22: 482.44
A23: DPS (Rp) | B23: 25 | C23: 155 | D23: 212.5 | E23: 277.5 | F23: 305 | G23: 381
A25: BJBR — Bank BJB
A26: Indikator | B26: 2021 | C26: 2022 | D26: 2023 | E26: 2024 | F26: 2025 | G26: TTM
A27: Pendapatan (Rp T) | B27: 8.934495 | C27: 9.730882 | D27: 8.216451 | E27: 7.991198 | F27: 9.07173 | G27: 9.283436
A28: Laba bersih (Rp T) | B28: 2.031858 | C28: 2.304376 | D28: 1.778395 | E28: 1.369463 | F28: 1.152816 | G28: 1.442705
A29: EPS (Rp) | B29: 206.52 | C29: 219.02 | D29: 169.03 | E29: 130.16 | F29: 109.57 | G29: 137.12
A30: DPS (Rp) | B30: n/a | C30: 99.11 | D30: 104.55 | E30: 95.05 | F30: 85.25 | G30: 85.54
A32: BJTM — Bank Jatim
A33: Indikator | B33: 2021 | C33: 2022 | D33: 2023 | E33: 2024 | F33: 2025 | G33: TTM
A34: Pendapatan (Rp T) | B34: 4.66892 | C34: 5.053997 | D34: 4.995384 | E34: 5.270241 | F34: 6.342611 | G34: 7.886075
A35: Laba bersih (Rp T) | B35: 1.52307 | C35: 1.542824 | D35: 1.470105 | E35: 1.281718 | F35: 1.545518 | G35: 1.56709
A36: EPS (Rp) | B36: 101.43 | C36: 102.75 | D36: 97.91 | E36: 85.36 | F36: 102.93 | G36: 104.36
A37: DPS (Rp) | B37: n/a | C37: 52.11 | D37: 53.09 | E37: 54.39 | F37: 54.71 | G37: 56.62
A39: TLKM — Telkom Indonesia
A40: Indikator | B40: 2021 | C40: 2022 | D40: 2023 | E40: 2024 | F40: 2025 | G40: TTM
A41: Pendapatan (Rp T) | B41: 143.21 | C41: 147.306 | D41: 149.216 | E41: 149.967 | F41: 146.742 | G41: 149.616
A42: Laba bersih (Rp T) | B42: 24.877 | C42: 20.736 | D42: 24.56 | E42: 22.403 | F42: 17.814 | G42: 17.964
A43: EPS (Rp) | B43: 251.13 | C43: 209.32 | D43: 247.92 | E43: 226.15 | F43: 179.83 | G43: 181.57
A44: DPS (Rp) | B44: n/a | C44: 149.97 | D44: 167.6 | E44: 178.5 | F44: 212.47 | G44: 223.17
A46: HMSP — HM Sampoerna
A47: Indikator | B47: 2021 | C47: 2022 | D47: 2023 | E47: 2024 | F47: 2025 | G47: TTM
...

Sheet Teknikal
A1: Level Teknikal
A2: Dihitung dari 50 sesi harian (11 Agu – 21 Okt 2026). MA100 tidak tersedia.
A4: Kode | B4: Harga | C4: MA20 | D4: vs MA20 | E4: MA50 | F4: vs MA50 | G4: MA200 | H4: vs MA200 | I4: RSI 14 | J4: MACD | K4: Signal | L4: Histogram | M4: ATR | N4: ATR %
A5: BMRI | B5: 3700 | C5: 3933.5 | D5: -0.059361891 | E5: 4131.78 | F5: -0.10450218 | G5: 4436.83 | H5: -0.16607127 | I5: 39.1 | J5: -154.48 | K5: -117.04 | L5: -37.44 | M5: 97.69 | N5: 0.0264
A6: BBRI | B6: 2810 | C6: 3029 | D6: -0.072301089 | E6: 3170 | F6: -0.11356467 | G6: 3264 | H6: -0.13909314 | I6: 39.4 | J6: -121.22 | K6: -85.8 | L6: -35.42 | M6: 88.46 | N6: 0.0315
A7: BBCA | B7: 5275 | C7: 5898.5 | D7: -0.10570484 | E7: 6203.22 | F7: -0.14963519 | G7: 6515.68 | H7: -0.19041451 | I7: 35 | J7: -286.27 | K7: -198.39 | L7: -87.88 | M7: 179.62 | N7: 0.0341
A8: BJBR | B8: 715 | C8: 746.5 | D8: -0.042196919 | E8: 771.9 | F8: -0.073714212 | G8: 796.35 | H8: -0.10215358 | I8: 37.4 | J8: -15.73 | K8: -11.97 | L8: -3.76 | M8: 11.92 | N8: 0.0167
A9: BJTM | B9: 498 | C9: 507.15 | D9: -0.018041999 | E9: 515.56 | F9: -0.034060051 | G9: 540.79 | H9: -0.079124984 | I9: 43.8 | J9: -6.18 | K9: -4.39 | L9: -1.79 | M9: 6.77 | N9: 0.0136
A10: TLKM | B10: 2080 | C10: 2231 | D10: -0.067682654 | E10: 2452.4 | F10: -0.15185125 | G10: 2911.15 | H10: -0.28550573 | I10: 39.5 | J10: -127.93 | K10: -106.32 | L10: -21.61 | M10: 82.31 | N10: 0.0396
A11: HMSP | B11: 645 | C11: 627.5 | D11: 0.027888446 | E11: 676.44 | F11: -0.046478623 | G11: 728.6 | H11: -0.1147406 | I11: 50 | J11: -17.77 | K11: -23.4 | L11: 5.63 | M11: 11.54 | N11: 0.0179
A12: CLEO | B12: 400 | C12: 416.3 | D12: -0.039154456 | E12: 414.76 | F12: -0.035586845 | G12: 403.09 | H12: -0.0076657818 | I12: 46.2 | J12: -2.68 | K12: 1.23 | L12: -3.91 | M12: 15.69 | N12: 0.0392
A13: ADRO | B13: 2360 | C13: 2482 | D13: -0.049153908 | E13: 2572.2 | F13: -0.082497473 | G13: 2390.1 | H13: -0.012593615 | I13: 41.9 | J13: -67.54 | K13: -47.45 | L13: -20.08 | M13: 64.62 | N13: 0.0274
A14: PTBA | B14: 3080 | C14: 3161 | D14: -0.025624802 | E14: 2911.8 | F14: 0.057764956 | G14: 2690.9 | H14: 0.14459846 | I14: 50.4 | J14: 38.1 | K14: 93.53 | L14: -55.43 | M14: 90.77 | N14: 0.0295
A15: PGEO | B15: 980 | C15: 976.75 | D15: 0.0033273611 | E15: 1019.8 | F15: -0.03902726 | G15: 1030.98 | H15: -0.049448098 | I15: 49.3 | J15: -23.87 | K15: -22.33 | L15: -1.54 | M15: 32.31 | N15: 0.033
A16: POWR | B16: 910 | C16: 936.25 | D16: -0.028037383 | E16: 925.2 | F16: -0.01642888 | G16: 769.65 | H16: 0.18235562 | I16: 47.9 | J16: -10.14 | K16: 2.1 | L16: -12.24 | M16: 26.92 | N16: 0.0296
... A18: TUGU | B18: 1345 | C18: 1456.5 | D18: -0.076553381 | E18: 1428.1 | F18: -0.058189202 | G18: 1274.2 | H18: 0.055564276 | I18: 43.3 | J18: -27.23 | K18: -1.6 | L18: -25.63 | M18: 51.15 | N18: 0.038

Sheet Catatan
A1: Catatan & Sumber
A3: • Data harga dan laporan keuangan: stockanalysis.com (S&P Global Market Intelligence), diakses 21 Oktober 2026.
A4: • Harga acuan: perdagangan 21 Oktober 2026 pukul 11.00–11.35 WIB. Pasar masih bergerak saat file ini dibuat.
A5: • Verifikasi berita: Kontan, Bisnis Indonesia, CNBC Indonesia, Antara, IDX Channel, Katadata.
A6: • Biaya ekuitas (COE) 13,5% = BI-Rate 5,75% + premi risiko ekuitas 7,75%.
A7: • Nilai wajar memakai PE wajar per emiten (judgment) dan/atau PB wajar serta DDM; lihat sheet 'Valuasi & Skenario'.
A8: • Broker summary dan foreign flow per saham TIDAK tersedia (data berbayar) — tidak diestimasi.
A9: • MA100 tidak tersedia dari sumber data; MA50/MA200 dari penyedia data, MA20/RSI/MACD dihitung dari 50 sesi.
A10: • ADRO: laporan 2021–2024 mencakup AADI yang dilepas Desember 2024; pertumbuhan historis tidak sebanding.
A11: • Bukan rekomendasi investasi. Kinerja masa lalu tidak menjamin hasil masa depan.

Sheet Log Bulanan
A1: Log Bulanan
A2: Satu baris per bulan — jejak apakah tesis investasi benar-benar berjalan.
A4: Bulan | B4: Tanggal | C4: IHSG | D4: Yield rata-rata | E4: MoS rata-rata | F4: Jumlah MoS > 0 | G4: Jumlah Buy | H4: Skor rata-rata | I4: Catatan
A5: 2026-10 | B5: 2026-10-21 | C5: 5236 | D5: 0.0876 | E5: 0.0785 | F5: 10 | G5: 7 | H5: 59.1 | I5: Baseline: IHSG -40% YTD, krisis MSCI, harga 21 Okt 2026
A31: Cara mengisi: di Google Sheets, jalankan skrip LogBulanan.gs (Extensions > Apps Script) - baris baru ditambahkan otomatis setiap awal bulan. Di Excel, salin baris terakhir lalu ubah tanggal dan angkanya setelah memperbarui harga.

Sheet Skor
A1: KODE | B1: FUND | C1: VAL | D1: DIV | E1: TECH | F1: RISK | G1: PROS | H1: TOTAL | I1: CATATAN
A2: BMRI | H2: 70.5 | I2: Isi 0–10; untuk emiten baru belum tersedia.
A3: BBRI | H3: 67 | I3: Isi 0–10; untuk emiten baru belum tersedia.
A4: BBCA | H4: 58 | I4: Isi 0–10; untuk emiten baru belum tersedia.
A5: BJBR | B5: 6 | C5: 8 | D5: 7 | E5: 4 | F5: 4 | G5: 5 | H5: 60.5
A6: BJTM | B6: 5 | C6: 9 | D6: 7 | E6: 4 | F6: 3 | G6: 5 | H6: 59
A7: TLKM | B7: 6 | C7: 8 | D7: 7 | E7: 3 | F7: 5 | G7: 6 | H7: 62
A8: HMSP | H8: 53 | I8: Isi 0–10; untuk emiten baru belum tersedia.
A9: CLEO | H9: 50.5 | I9: Isi 0–10; untuk emiten baru belum tersedia.
A10: ADRO | B10: 7 | C10: 5 | D10: 6 | E10: 5 | F10: 5 | G10: 7 | H10: 58.5
A11: PTBA | B11: 6 | C11: 4 | D11: 3 | E11: 7 | F11: 5 | G11: 7 | H11: 49
A12: PGEO | B12: 6 | C12: 3 | D12: 5 | E12: 5 | F12: 6 | G12: 7 | H12: 51.5
A13: POWR | B13: 7 | C13: 3 | D13: 7 | E13: 7 | F13: 5 | G13: 7 | H13: 59
A14: IPCC | B14: 8 | C14: 7 | D14: 8 | E14: 3 | F14: 3 | G14: 6 | H14: 63.5
A15: TUGU | B15: 7 | C15: 7 | D15: 8 | E15: 4 | F15: 5 | G15: 6 | H15: 65.5

Sheet Data Keuangan
A1: KODE | B1: NAMA | C1: TAHUN | D1: PERIODE | E1: MATA_UANG | F1: SATUAN | G1: PENDAPATAN | H1: LABA_OPERASI | I1: LABA_BERSIH | J1: EPS | K1: DPS | L1: TOTAL_ASET | M1: TOTAL_EKUITAS | N1: TOTAL_UTANG | O1: KAS | P1: EBITDA | Q1: FCF | R1: SHARES | S1: SUMBER | T1: CATATAN
A2: BMRI | B2: Bank Mandiri | C2: 2021 | D2: FY | E2: IDR | F2: Triliun | G2: 86.552332 | I2: 28.028155 | J2: 300.53 | S2: Data Keuangan 2021-2025
A3: BMRI | B3: Bank Mandiri | C3: 2022 | D3: FY | E3: IDR | F3: Triliun | G3: 109.39753 | I3: 41.170637 | J3: 441.26 | K3: 180.32 | S3: Data Keuangan 2021-2025
A4: BMRI | B4: Bank Mandiri | C4: 2023 | D4: FY | E4: IDR | F4: Triliun | G4: 127.45457 | I4: 55.060057 | J4: 589.93 | K4: 264.67 | S4: Data Keuangan 2021-2025
A5: BMRI | B5: Bank Mandiri | C5: 2024 | D5: FY | E5: IDR | F5: Triliun | G5: 134.73536 | I5: 55.782742 | J5: 597.67 | K5: 353.96 | S5: Data Keuangan 2021-2025
A6: BMRI | B6: Bank Mandiri | C6: 2025 | D6: FY | E6: IDR | F6: Triliun | G6: 144.81748 | I6: 56.29395 | J6: 603.23 | K6: 466.18 | S6: Data Keuangan 2021-2025
A7: BMRI | B7: Bank Mandiri | C7: 2026 | D7: TTM | E7: IDR | F7: Triliun | G7: 139.87246 | I7: 64.097809 | J7: 687.14 | K7: 476.96 | S7: Data Keuangan 2021-2025
A8: BBRI | B8: Bank Rakyat Indonesia | C8: 2021 | D8: FY | E8: IDR | F8: Triliun | G8: 111.5854 | I8: 31.066592 | J8: 237.96 | S8: Data Keuangan 2021-2025
A9: BBRI | B9: Bank Rakyat Indonesia | C9: 2022 | D9: FY | E9: IDR | F9: Triliun | G9: 125.99009 | I9: 51.170312 | J9: 338 | K9: 174.25 | S9: Data Keuangan 2021-2025
A10: BBRI | B10: Bank Rakyat Indonesia | C10: 2023 | D10: FY | E10: IDR | F10: Triliun | G10: 137.05849 | I10: 60.099863 | J10: 398 | K10: 288.22 | S10: Data Keuangan 2021-2025
A11: BBRI | B11: Bank Rakyat Indonesia | C11: 2024 | D11: FY | E11: IDR | F11: Triliun | G11: 131.25363 | I11: 59.944649 | J11: 397.69 | K11: 319 | S11: Data Keuangan 2021-2025
A12: BBRI | B12: Bank Rakyat Indonesia | C12: 2025 | D12: FY | E12: IDR | F12: Triliun | G12: 140.20883 | I12: 56.652384 | J12: 376 | K12: 345.4 | S12: Data Keuangan 2021-2025
A13: BBRI | B13: Bank Rakyat Indonesia | C13: 2026 | D13: TTM | E13: IDR | F13: Triliun | G13: 146.8427 | I13: 61.241085 | J13: 406.65 | K13: 346 | S13: Data Keuangan 2021-2025
A14: BBCA | B14: Bank Central Asia | C14: 2021 | D14: FY | E14: IDR | F14: Triliun | G14: 69.144054 | I14: 31.42266 | J14: 254.9 | K14: 25 | S14: Data Keuangan 2021-2025
A15: BBCA | B15: Bank Central Asia | C15: 2022 | D15: FY | E15: IDR | F15: Triliun | G15: 82.942762 | I15: 40.735722 | J15: 330 | K15: 155 | S15: Data Keuangan 2021-2025
A16: BBCA | B16: Bank Central Asia | C16: 2023 | D16: FY | E16: IDR | F16: Triliun | G16: 97.444628 | I16: 48.639122 | J16: 394.56 | K16: 212.5 | S16: Data Keuangan 2021-2025
A17: BBCA | B17: Bank Central Asia | C17: 2024 | D17: FY | E17: IDR | F17: Triliun | G17: 104.5166 | I17: 54.836305 | J17: 444.83 | K17: 277.5 | S17: Data Keuangan 2021-2025
A18: BBCA | B18: Bank Central Asia | C18: 2025 | D18: FY | E18: IDR | F18: Triliun | G18: 107.98561 | I18: 57.537287 | J18: 466.85 | K18: 305 | S18: Data Keuangan 2021-2025
A19: BBCA | B19: Bank Central Asia | C19: 2026 | D19: TTM | E19: IDR | F19: Triliun | G19: 110.55051 | I19: 59.355699 | J19: 482.44 | K19: 381 | S19: Data Keuangan 2021-2025
A20: BJBR | B20: Bank BJB | C20: 2021 | D20: FY | E20: IDR | F20: Triliun | G20: 8.934495 | I20: 2.031858 | J20: 206.52 | S20: Data Keuangan 2021-2025
A21: BJBR | B21: Bank BJB | C21: 2022 | D21: FY | E21: IDR | F21: Triliun | G21: 9.730882 | I21: 2.304376 | J21: 219.02 | K21: 99.11 | S21: Data Keuangan 2021-2025
A22: BJBR | B22: Bank BJB | C22: 2023 | D22: FY | E22: IDR | F22: Triliun | G22: 8.216451 | I22: 1.778395 | J22: 169.03 | K22: 104.55 | S22: Data Keuangan 2021-2025
A23: BJBR | B23: Bank BJB | C23: 2024 | D23: FY | E23: IDR | F23: Triliun | G23: 7.991198 | I23: 1.369463 | J23: 130.16 | K23: 95.05 | S23: Data Keuangan 2021-2025
A24: BJBR | B24: Bank BJB | C24: 2025 | D24: FY | E24: IDR | F24: Triliun | G24: 9.07173 | I24: 1.152816 | J24: 109.57 | K24: 85.25 | S24: Data Keuangan 2021-2025
A25: BJBR | B25: Bank BJB | C25: 2026 | D25: TTM | E25: IDR | F25: Triliun | G25: 9.283436 | I25: 1.442705 | J25: 137.12 | K25: 85.54 | L25: 171.7506 | M25: 19.77 | N25: 43.64 | O25: 21.87 | S25: Data Keuangan 2021-2025
A26: BJTM | B26: Bank Jatim | C26: 2021 | D26: FY | E26: IDR | F26: Triliun | G26: 4.66892 | I26: 1.52307 | J26: 101.43 | S26: Data Keuangan 2021-2025
A27: BJTM | B27: Bank Jatim | C27: 2022 | D27: FY | E27: IDR | F27: Triliun | G27: 5.053997 | I27: 1.542824 | J27: 102.75 | K27: 52.11 | S27: Data Keuangan 2021-2025
A28: BJTM | B28: Bank Jatim | C28: 2023 | D28: FY | E28: IDR | F28: Triliun | G28: 4.995384 | I28: 1.470105 | J28: 97.91 | K28: 53.09 | S28: Data Keuangan 2021-2025
A29: BJTM | B29: Bank Jatim | C29: 2024 | D29: FY | E29: IDR | F29: Triliun | G29: 5.270241 | I29: 1.281718 | J29: 85.36 | K29: 54.39 | S29: Data Keuangan 2021-2025
A30: BJTM | B30: Bank Jatim | C30: 2025 | D30: FY | E30: IDR | F30: Triliun | G30: 6.342611 | I30: 1.545518 | J30: 102.93 | K30: 54.71 | S30: Data Keuangan 2021-2025
A31: BJTM | B31: Bank Jatim | C31: 2026 | D31: TTM | E31: IDR | F31: Triliun | G31: 7.886075 | I31: 1.56709 | J31: 104.36 | K31: 56.62 | L31: 107.33493 | M31: 21.64 | N31: 15.1 | O31: 15.72 | S31: Data Keuangan 2021-2025
A32: TLKM | B32: Telkom Indonesia | C32: 2021 | D32: FY | E32: IDR | F32: Triliun | G32: 143.21 | I32: 24.877 | J32: 251.13 | S32: Data Keuangan 2021-2025
A33: TLKM | B33: Telkom Indonesia | C33: 2022 | D33: FY | E33: IDR | F33: Triliun | G33: 147.306 | I33: 20.736 | J33: 209.32 | K33: 149.97 | S33: Data Keuangan 2021-2025
A34: TLKM | B34: Telkom Indonesia | C34: 2023 | D34: FY | E34: IDR | F34: Triliun | G34: 149.216 | I34: 24.56 | J34: 247.92 | K34: 167.6 | S34: Data Keuangan 2021-2025
A35: TLKM | B35: Telkom Indonesia | C35: 2024 | D35: FY | E35: IDR | F35: Triliun | G35: 149.967 | I35: 22.403 | J35: 226.15 | K35: 178.5 | S35: Data Keuangan 2021-2025
A36: TLKM | B36: Telkom Indonesia | C36: 2025 | D36: FY | E36: IDR | F36: Triliun | G36: 146.742 | I36: 17.814 | J36: 179.83 | K36: 212.47 | S36: Data Keuangan 2021-2025
A37: TLKM | B37: Telkom Indonesia | C37: 2026 | D37: TTM | E37: IDR | F37: Triliun | G37: 149.616 | I37: 17.964 | J37: 181.57 | K37: 223.17 | L37: 236.99208 | M37: 134.85 | N37: 80.89 | O37: 56.48 | S37: Data Keuangan 2021-2025
A38: HMSP | B38: HM Sampoerna | C38: 2021 | D38: FY | E38: IDR | F38: Triliun | G38: 41.512611 | I38: 7.137097 | J38: 61.36 | K38: 72.8 | S38: Data Keuangan 2021-2025
A39: HMSP | B39: HM Sampoerna | C39: 2022 | D39: FY | E39: IDR | F39: Triliun | G39: 45.616356 | I39: 6.323744 | J39: 54.37 | K39: 63.3 | S39: Data Keuangan 2021-2025
A40: HMSP | B40: HM Sampoerna | C40: 2023 | D40: FY | E40: IDR | F40: Triliun | G40: 53.106365 | I40: 8.096811 | J40: 69.61 | K40: 54.7 | S40: Data Keuangan 2021-2025
...

Sheet Dividen
A1: KODE | B1: TAHUN | C1: DPS | D1: TIPE
A2: BMRI | B2: 2022 | C2: 180.32 | D2: FINAL
A3: BMRI | B3: 2023 | C3: 264.67 | D3: FINAL
A4: BMRI | B4: 2024 | C4: 353.96 | D4: FINAL
A5: BMRI | B5: 2025 | C5: 466.18 | D5: FINAL
A6: BMRI | B6: 2026 | C6: 476.96 | D6: TTM
A7: BBRI | B7: 2022 | C7: 174.25 | D7: FINAL
A8: BBRI | B8: 2023 | C8: 288.22 | D8: FINAL
A9: BBRI | B9: 2024 | C9: 319 | D9: FINAL
A10: BBRI | B10: 2025 | C10: 345.4 | D10: FINAL
A11: BBRI | B11: 2026 | C11: 346 | D11: TTM
A12: BBCA | B12: 2021 | C12: 25 | D12: FINAL
A13: BBCA | B13: 2022 | C13: 155 | D13: FINAL
... A73: TUGU | B73: 2026 | C73: 99.99 | D73: TTM

Sheet Ringkasan 5 Tahun
A1: KODE | B1: NAMA | C1: PENDAPATAN TTM | D1: LABA BERSIH TTM | E1: EPS TTM | F1: DPS TTM | G1: CAGR PENDAPATAN | H1: CAGR LABA | I1: ROE | J1: DER | K1: PM | L1: OM
A2: BMRI | B2: Bank Mandiri | C2: 139.87246 | D2: 64.097809 | E2: 687.14 | F2: 476.96 | G2: 0.10075505 | H2: 0.17991232 | K2: 0.45825898
A3: BBRI | B3: Bank Rakyat Indonesia | C3: 146.8427 | D3: 61.241085 | E3: 406.65 | F3: 346 | G3: 0.056450117 | H3: 0.14538068 | K3: 0.41705229
A4: BBCA | B4: Bank Central Asia | C4: 110.55051 | D4: 59.355699 | E4: 482.44 | F4: 381 | G4: 0.098401656 | H4: 0.13564841 | K4: 0.53691024
A5: BJBR | B5: Bank BJB | C5: 9.283436 | D5: 1.442705 | E5: 137.12 | F5: 85.54 | G5: 0.0076918533 | H5: -0.06619362 | K5: 0.15540636
A6: BJTM | B6: Bank Jatim | C6: 7.886075 | D6: 1.56709 | E6: 104.36 | F6: 56.62 | G6: 0.11052642 | H6: 0.0057147395 | K6: 0.19871609
A7: TLKM | B7: Telkom Indonesia | C7: 149.616 | D7: 17.964 | E7: 181.57 | F7: 223.17 | G7: 0.008790396 | H7: -0.063040092 | K7: 0.12006737
A8: HMSP | B8: HM Sampoerna | C8: 52.301117 | D8: 8.613279 | E8: 73.73 | F8: 56.3 | G8: 0.047288134 | H8: 0.03831561 | K8: 0.16468633
A9: CLEO | B9: Sariguna Primatirta | C9: 3.150473 | D9: 0.430099 | E9: 17.92 | F9: 2.5 | G9: 0.23344307 | H9: 0.18936811 | K9: 0.13651887
A10: ADRO | B10: Alamtri Resources | D10: 582.12 | E10: 361.18 | F10: 263.4 | H10: -0.090127435
A11: PTBA | B11: Bukit Asam | C11: 44.227234 | D11: 4.746812 | E11: 411.7 | F11: 114.51 | G11: 0.086122308 | H11: -0.097068404 | K11: 0.10732781
A12: PGEO | B12: Pertamina Geothermal | D12: 148.36 | E12: 63.17 | F12: 49.44 | H12: 0.11762953
A13: POWR | B13: Cikarang Listrindo | D13: 69.55 | E13: 78.53 | F13: 73.74 | H13: -0.051172385
A14: IPCC | B14: Indonesia Kendaraan Terminal | C14: 0.927911 | D14: 0.245949 | E14: 135.26 | F14: 112.85 | G14: 0.12416626 | H14: 0.32573808 | K14: 0.26505667
A15: TUGU | B15: Asuransi Tugu Pratama | C15: 5.75154 | D15: 0.919788 | E15: 258.69 | F15: 99.99 | G15: 0.16346546 | H15: 0.23785078 | K15: 0.1599203

Sheet Historik
A1: KODE | B1: MINGGU | C1: PERIODE | D1: HARGA
D2: Isi minimal 10 minggu per saham untuk grafik tren harga.
